Workbook

Sheet Ganancias
B1: 2023 | C1: 2024
A2: enero | C2: =+'Ingresos 2024'!I15 -> 10110714
A3: febrero | B3: =+'Ingresos 2023'!J19 -> 2283600 | C3: =+'Ingresos 2024'!I122 -> 10469071
A4: marzo | B4: =+'Ingresos 2023'!J86 -> 15288600 | C4: =+'Ingresos 2024'!I269 -> 27516714
A5: abril | B5: =+'Ingresos 2023'!J158 -> 14433500 | G5: 2024 | H5: 110000000
A6: mayo | B6: =+'Ingresos 2023'!J236 -> 19622500 | G6: 2023 | H6: =160000000-70000000 -> 90000000
A7: junio | B7: =+'Ingresos 2023'!J325 -> 16771500 | G7: por lote | H7: =+H5+H6 -> 200000000 | K7: =+H7*100/60000000 -> 333.33333 | L7: %
A8: julio | B8: =+'Ingresos 2023'!J407 -> 14122500 | G8: por año | H8: =+H7/2 -> 100000000 | K8: =+H8*100/60000000 -> 166.66667 | L8: %
A9: agosto | B9: =+'Ingresos 2023'!J489 -> 16654000 | G9: por mes | H9: =+H8/12 -> 8333333.3 | K9: =+H9*100/60000000 -> 13.888889 | L9: %
A10: septiembre | B10: =+'Ingresos 2023'!J593 -> 7792000
A11: octubre | B11: =+'Ingresos 2023'!J681 -> 16975143
A12: noviembre | B12: =+'Ingresos 2023'!J799 -> 12457429 | G12: 2 gallineros cargados | I12: =+H9+H9*1.3/2 -> 13750000
A13: diciembre | B13: =+'Ingresos 2023'!J901 -> 8669714.3
E15: 13613000 | F15: ingreso mensual promedio 2000 aves
E16: =+E15/1800 -> 7562.7778 | F16: por plancha

Sheet Ingresos 2023
A1: Fecha | B1: Cliente | C1: Cantidad | D1: Concepto | E1: Precio Unitario | F1: Ventas | G1: Precio promedio
C2: =+SUM(C4:C1000) -> 17705 | F2: =+SUM(F3:F1000) -> 388554000 | G2: =+F2/C2 -> 21946.004
A3: 44953 | C3: 280 | D3: Bolsas de balanceado | E3: =+F3/C3 -> 500 | F3: 140000
A4: 44956 | C4: 10 | D4: C | E4: =+F4/C4 -> 15000 | F4: 150000
A5: 44957 | C5: 1 | D5: C | E5: =+F5/C5 -> 20000 | F5: 20000
A6: 44958 | C6: 11 | D6: C | E6: =+F6/C6 -> 18000 | F6: 198000 | G6: =+SUM(F6:F72)/SUM(C6:C72) -> 19769.011 | I6: Viajes | J6: 24
A7: 44959 | C7: 15 | D7: Huevo menudeo | E7: =+F7/C7 -> 666.66667 | F7: 10000
A8: 44962 | B8: Ani | C8: 10 | D8: B | E8: =+F8/C8 -> 18000 | F8: 180000 | I8: Costos | L8: Precios
A9: 44963 | B9: Coti | C9: 35 | D9: C | E9: =+F9/C9 -> 17000 | F9: 595000 | I9: Viajes | J9: =60/100*9*M9*J6 -> 972000 | L9: Combustible | M9: 7500 | N9: Gs/L
A10: 44963 | B10: Fredi | C10: 15 | D10: B | E10: =+F10/C10 -> 19000 | F10: 285000 | I10: Cubetas | J10: =+SUM(C6:C72)*M10 -> 526000 | L10: Cubetas | M10: 500 | N10: Gs/unidad
A11: 44964 | B11: Kiti | C11: 5 | D11: C | E11: =+F11/C11 -> 17800 | F11: 89000 | I11: Balanceado | J11: =8.6*28*M11 -> 15170400 | L11: Balanceado | M11: 63000 | N11: Gs/bolsa
B12: Luz Villasanti | C12: 3 | D12: B | E12: =+F12/C12 -> 20000 | F12: 60000 | I12: Personales | J12: =+M12*28 -> 1680000 | L12: Personal | M12: 60000 | N12: Gs/dia
B13: Ani | C13: 3 | D13: B | E13: =+F13/C13 -> 18000 | F13: 54000 | I13: Agua | J13: 15000
A14: 44965 | B14: Ani | C14: 5 | D14: B | E14: =+F14/C14 -> 18000 | F14: 90000 | I14: Vitaminas, etc | J14: 150000
A15: 44967 | B15: Vecinos | C15: 1 | D15: B | E15: =+F15/C15 -> 20000 | F15: 20000 | I15: TOTAL COSTOS | J15: =+SUM(J9:J14) -> 18513400
B16: Panadería | C16: 2 | D16: B | E16: =+F16/C16 -> 21000 | F16: 42000
B17: Ña Ernesta | C17: 10 | D17: B | E17: =+F17/C17 -> 20000 | F17: 200000 | I17: TOTAL INGRESOS | J17: =+SUM(F6:F72) -> 20797000
B18: Vecinos | C18: 2 | D18: Huevo picado | E18: =+F18/C18 -> 10000 | F18: 20000
B19: Coti | C19: 25 | D19: C | E19: =+F19/C19 -> 17000 | F19: 425000 | I19: TOTAL GANANCIA | J19: =+J17-J15 -> 2283600
A20: 44969 | B20: Edelio | C20: 3 | D20: C | E20: =+F20/C20 -> 18000 | F20: 54000
A21: 44970 | B21: Ani | C21: 5 | D21: B | E21: =+F21/C21 -> 18000 | F21: 90000
B22: Dalila | C22: 50 | D22: B | E22: =+F22/C22 -> 20000 | F22: 1000000
B23: Fredi | C23: 22 | D23: B | E23: =+F23/C23 -> 19000 | F23: 418000
A24: 44971 | B24: Fredi | C24: 22 | D24: B | E24: =+F24/C24 -> 19000 | F24: 418000
B25: Ña Oso | C25: 5 | D25: A | E25: =+F25/C25 -> 21000 | F25: 105000
A26: 44972 | B26: Vecinos | C26: 1 | D26: Huevo picado | E26: =+F26/C26 -> 10000 | F26: 10000
B27: Coti | C27: 45 | D27: C | E27: =+F27/C27 -> 17000 | F27: 765000 | J27: falta pagar 281000
A28: 44973 | B28: Elsa | C28: 6 | D28: C | E28: =+F28/C28 -> 19000 | F28: 114000
B29: Fredi | C29: 12 | D29: B | E29: =+F29/C29 -> 19000 | F29: 228000
B30: Dalila | C30: 50 | D30: B | E30: =+F30/C30 -> 20000 | F30: 1000000
C31: 2 | D31: S | E31: =+F31/C31 -> 22000 | F31: 44000
C32: 4 | D32: A | E32: =+F32/C32 -> 20000 | F32: 80000
C33: 3 | D33: B | E33: =+F33/C33 -> 20000 | F33: 60000
A34: 44974 | B34: Fredi | C34: 25 | D34: B | E34: =+F34/C34 -> 19000 | F34: 475000
B35: Blanqui | C35: 24 | D35: C | E35: =+F35/C35 -> 19000 | F35: 456000
B36: Blanqui | C36: 40 | D36: B | E36: =+F36/C36 -> 20000 | F36: 800000
B37: Magali Ovelar | C37: 2 | D37: A | E37: =+F37/C37 -> 22000 | F37: 44000
A38: 44975 | B38: Ña Ernesta | C38: 10 | D38: A | E38: =+F38/C38 -> 22000 | F38: 220000
B39: Fredi | C39: 20 | D39: B | E39: =+F39/C39 -> 20000 | F39: 400000
B40: Blanqui | C40: 25 | D40: B | E40: =+F40/C40 -> 20000 | F40: 500000
...

Sheet Ingresos 2024
A1: Fecha | B1: Cliente | C1: Cantidad | D1: Concepto | E1: Precio Unitario | F1: Ingreso | G1: Precio promedio
A2: 45293 | B2: Marian Elenice | C2: 20 | D2: A | E2: 21000 | F2: =+E2*C2 -> 420000 | G2: =+SUM(F2:F108)/SUM(C2:C108) -> 19249.709 | H2: Viajes | I2: 30
B3: Ysapy | C3: 5 | D3: S | E3: 23000 | F3: =+E3*C3 -> 115000
B4: Agus | C4: 3 | D4: S | E4: 22000 | F4: =+E4*C4 -> 66000 | H4: Costos | K4: Precios
B5: Fredi | C5: 20 | D5: S | E5: 21000 | F5: =+E5*C5 -> 420000 | H5: Viajes | I5: =60/100*9*L5*I2 -> 1215000 | K5: Combustible | L5: 7500 | M5: Gs/L
B6: Fada | C6: 45 | D6: A | E6: 20000 | F6: =+E6*C6 -> 900000 | H6: Cubetas | I6: =+SUM(C2:C108)*L6 -> 859000 | K6: Cubetas | L6: 500 | M6: Gs/unidad
B7: Dalila | C7: 40 | D7: A | E7: 20000 | F7: =+E7*C7 -> 800000 | H7: Balanceado | I7: =+L7*9*31 -> 17577000 | K7: Balanceado | L7: 63000 | M7: Gs/bolsa
B8: Dalila | C8: 15 | D8: S | E8: 21000 | F8: =+E8*C8 -> 315000 | H8: Personales | I8: =+L8*31 -> 3144285.7 | K8: Personal | L8: =500000/7+30000 -> 101428.57 | M8: Gs/dia
A9: 45294 | B9: Coti | C9: 25 | D9: A | E9: 19000 | F9: =+E9*C9 -> 475000 | H9: Agua | I9: 15000
A10: 45295 | B10: Derlis Paredes | C10: 12 | D10: S | E10: 21000 | F10: =+E10*C10 -> 252000 | H10: Vitaminas, etc | I10: 150000
B11: Marian Elenice | C11: 20 | D11: A | E11: 21000 | F11: =+E11*C11 -> 420000 | H11: TOTAL COSTOS | I11: =+SUM(I5:I10) -> 22960286
B12: Abner | C12: 6 | D12: J | E12: 24000 | F12: =+E12*C12 -> 144000
B13: Dalila | C13: 11 | D13: S | E13: 21000 | F13: =+E13*C13 -> 231000 | H13: TOTAL INGRESOS | I13: =+SUM(F2:F108) -> 33071000
B14: Dalila | C14: 35 | D14: A | E14: 20000 | F14: =+E14*C14 -> 700000
B15: Kiti | C15: 25 | D15: B | E15: 20000 | F15: =+E15*C15 -> 500000 | H15: TOTAL GANACIA | I15: =+I13-I11 -> 10110714
A16: 45297 | B16: Pastora | C16: 5 | D16: J | E16: 24000 | F16: =+E16*C16 -> 120000
B17: Noelia | C17: 8 | D17: B | E17: 20000 | F17: =+E17*C17 -> 160000
B18: Fredi | C18: 15 | D18: S | E18: 21000 | F18: =+E18*C18 -> 315000
B19: Dalila | C19: 40 | D19: A | E19: 20000 | F19: =+E19*C19 -> 800000
B20: Dalila | C20: 6 | D20: S | E20: 21000 | F20: =+E20*C20 -> 126000
B21: Despensa Lucero | C21: 5 | D21: A | E21: 21000 | F21: =+E21*C21 -> 105000
B22: Agus | C22: 3 | D22: A | E22: 21000 | F22: =+E22*C22 -> 63000
B23: Ysapy | C23: 4 | D23: A | E23: 22000 | F23: =+E23*C23 -> 88000
A24: 45298 | B24: Coti | C24: 22 | D24: A | E24: 20000 | F24: =+E24*C24 -> 440000
B25: Coti | C25: 6 | D25: B | E25: 18000 | F25: =+E25*C25 -> 108000
A26: 45299 | B26: Fada | C26: 50 | D26: A | E26: 20000 | F26: =+E26*C26 -> 1000000
B27: Ingrid | C27: 6 | D27: A | E27: 22000 | F27: =+E27*C27 -> 132000
A28: 45300 | B28: Alianza | C28: 15 | D28: S | E28: 23000 | F28: =+E28*C28 -> 345000
B29: Marian Elenice | C29: 15 | D29: A | E29: 21000 | F29: =+E29*C29 -> 315000
B30: Fredi | C30: 18 | D30: S | E30: 21000 | F30: =+E30*C30 -> 378000
C31: 100 | D31: BOLSAS | E31: 500 | F31: =+E31*C31 -> 50000
A32: 45301 | B32: Derlis Paredes | C32: 15 | D32: S | E32: 21000 | F32: =+E32*C32 -> 315000
B33: Agus | C33: 3 | D33: S | E33: 22000 | F33: =+E33*C33 -> 66000
B34: Dalila | C34: 47 | D34: A | E34: 20000 | F34: =+E34*C34 -> 940000
B35: Benito | C35: 15 | D35: A | E35: 20000 | F35: =+E35*C35 -> 300000
A36: 45302 | B36: Coti | C36: 20 | D36: A | E36: 20000 | F36: =+E36*C36 -> 400000
B37: Coti | C37: 13 | D37: B | E37: 18000 | F37: =+E37*C37 -> 234000
A38: 45303 | B38: Zuni SM | C38: 3 | D38: A | E38: 22000 | F38: =+E38*C38 -> 66000
B39: Vecinos | C39: 1 | D39: B | E39: 20000 | F39: =+E39*C39 -> 20000
B40: Ysapy | C40: 4 | D40: S | E40: 23000 | F40: =+E40*C40 -> 92000
...

Sheet Egresos
A1: Fecha | B1: Concepto | C1: Cantidad | D1: Precio Unitario | E1: Cliente | F1: Observaciones
A3: 44805 | B3: Cascarilla de arroz | C3: 1 | D3: 2600000
A4: 44816 | B4: AVT 40 | C4: 1 | D4: 160000 | E4: Cooka
A5: 44816 | B5: Poly-phen | C5: 1 | D5: 348000 | E5: Bionatural
A6: 44816 | B6: Potenbac polvo 100g | C6: 1 | D6: 157000 | E6: Bionatural
A7: 44816 | B7: Cables y portafoco
A8: 44817 | B8: Carpa negra 15x4
A9: 44788 | B9: Diluyente | C9: 2 | D9: 35000 | E9: Bionatural
A10: 44820 | B10: Pollitas HyLine Brown | C10: 2000 | D10: =+[1]Egresos!E10/C10 -> 0
A11: 44820 | B11: Balanceado Inicio | C11: 10 | D11: =+[1]Egresos!E11/C11 -> #VALUE! | E11: Cooka
A12: 44820 | B12: Maiz molido 30 kg | C12: 1 | E12: Cooka
A13: 44820 | B13: Stop Stress | C13: 1 | D13: 245000 | E13: Cooka
A14: 44820 | B14: Balanza miligramo
A15: 44820 | B15: Balde para agua | C15: 2 | D15: =+[1]Egresos!E15/C15 -> 0
A16: 44820 | B16: Balde para agua | C16: 2 | D16: =+[1]Egresos!E16/C16 -> 0
A17: 44826 | B17: Vacunas
A18: 44826 | B18: Balanceado Inicio | C18: 15 | D18: =+[1]Egresos!E18/C18 -> 0
A19: 44827 | B19: Personal vacunación | C19: 2 | D19: 30000
A20: 44834 | B20: Balanceado Inicio | C20: 20 | D20: =+[1]Egresos!E20/C20 -> 0
A21: 44834 | B21: Vacunas
A22: 44834 | B22: Personal control | C22: 2 | D22: 60000
A23: 44840 | B23: Bebederos pendulares | C23: 6 | D23: =+[1]Egresos!E23/C23 -> 0
A24: 44841 | B24: Vacunas
A25: 44841 | B25: Balanceado Inicio | C25: 18 | D25: =+[1]Egresos!E25/C25 -> 0
A26: 44845 | B26: Personal vacunación | C26: 2 | D26: 30000
A27: 44848 | B27: Vacunas
A28: 44848 | B28: Balanceado Inicio | C28: 20 | D28: =+[1]Egresos!E28/C28 -> 0
A29: 44849 | B29: Vacunas
A30: 44852 | B30: Bebederos pendulares | C30: 8 | D30: =+[1]Egresos!E30/C30 -> 0
A31: 44855 | B31: Balanceado Inicio | C31: 20 | D31: =+[1]Egresos!E31/C31 -> 0
A32: 44860 | B32: Despique | C32: 2000 | D32: =+[1]Egresos!E32/C32 -> 0
A33: 44860 | B33: Personal despique | C33: 1 | D33: 60000
A34: 44862 | B34: Balanceado Inicio | C34: 25 | D34: =+[1]Egresos!E34/C34 -> 0
A35: 44866 | B35: Febenlasca 1L | C35: 1 | D35: =+[1]Egresos!E35/C35 -> 0
A36: 44869 | B36: Balanceado Inicio | C36: 30 | D36: =+[1]Egresos!E36/C36 -> 0
A37: 44877 | B37: Balanceado Crecimiento | C37: 25 | D37: =+[1]Egresos!E37/C37 -> 0
A38: 44883 | B38: Balanceado Crecimiento | C38: 35 | D38: =+[1]Egresos!E38/C38 -> 0
A39: 44891 | B39: Balanceado Crecimiento | C39: 30 | D39: =+[1]Egresos!E39/C39 -> 0
A40: 44893 | B40: Bolsas de balanceado | C40: 200 | D40: =+#REF!/C40 -> #REF! | E40: Venialvos
A41: 44897 | B41: Balanceado Crecimiento | C41: 35 | D41: =+[1]Egresos!E41/C41 -> 0
...

Sheet Hoja1
A1: Fecha | B1: Ingreso | C1: Egreso | D1: Concepto | E1: Cantidad | F1: Precio Unitario | G1: Cliente | H1: Observaciones
B2: =+SUM(B3:B473) -> 33415000 | C2: =+SUM(C3:C451) -> 79839000
A3: 44805 | C3: 2600000 | D3: Cascarilla de arroz | E3: 1 | F3: 2600000
A4: 44816 | C4: 160000 | D4: AVT 40 | E4: 1 | F4: 160000 | G4: Cooka
A5: 44816 | C5: 348000 | D5: Poly-phen | E5: 1 | F5: 348000 | G5: Bionatural
A6: 44816 | C6: 157000 | D6: Potenbac polvo 100g | E6: 1 | F6: 157000 | G6: Bionatural
A7: 44816 | C7: 120000 | D7: Cables y portafoco
A8: 44817 | C8: 75000 | D8: Carpa negra 15x4
A9: 44788 | C9: 70000 | D9: Diluyente | E9: 2 | F9: 35000 | G9: Bionatural
A10: 44820 | C10: 14200000 | D10: Pollitas HyLine Brown | E10: 2000 | F10: =+C10/E10 -> 7100
A11: 44820 | C11: 730000 | D11: Balanceado Inicio | E11: 10 | F11: =+C11/E11 -> 73000 | G11: Cooka
A12: 44820 | C12: 60000 | D12: Maiz molido 30 kg | E12: 1 | G12: Cooka
A13: 44820 | C13: 245000 | D13: Stop Stress | E13: 1 | F13: 245000 | G13: Cooka
A14: 44820 | C14: 32000 | D14: Balanza miligramo
A15: 44820 | C15: 55000 | D15: Balde para agua | E15: 2 | F15: =+C15/E15 -> 27500
A16: 44820 | C16: 50000 | D16: Balde para agua | E16: 2 | F16: =+C16/E16 -> 25000
A17: 44826 | C17: 545000 | D17: Vacunas
A18: 44826 | C18: 1095000 | D18: Balanceado Inicio | E18: 15 | F18: =+C18/E18 -> 73000
A19: 44827 | C19: 60000 | D19: Personal vacunación | E19: 2 | F19: 30000
A20: 44834 | C20: 1460000 | D20: Balanceado Inicio | E20: 20 | F20: =+C20/E20 -> 73000
A21: 44834 | C21: 120000 | D21: Vacunas
A22: 44834 | C22: 120000 | D22: Personal control | E22: 2 | F22: 60000
A23: 44840 | C23: 270000 | D23: Bebederos pendulares | E23: 6 | F23: =+C23/E23 -> 45000
A24: 44841 | C24: 84000 | D24: Vacunas
A25: 44841 | C25: 1314000 | D25: Balanceado Inicio | E25: 18 | F25: =+C25/E25 -> 73000
A26: 44845 | C26: 60000 | D26: Personal vacunación | E26: 2 | F26: 30000
A27: 44848 | C27: 165000 | D27: Vacunas
A28: 44848 | C28: 1460000 | D28: Balanceado Inicio | E28: 20 | F28: =+C28/E28 -> 73000
A29: 44849 | C29: 140000 | D29: Vacunas
A30: 44852 | C30: 360000 | D30: Bebederos pendulares | E30: 8 | F30: =+C30/E30 -> 45000
A31: 44855 | C31: 1460000 | D31: Balanceado Inicio | E31: 20 | F31: =+C31/E31 -> 73000
A32: 44860 | C32: 720000 | D32: Despique | E32: 2000 | F32: =+C32/E32 -> 360
A33: 44860 | C33: 60000 | D33: Personal despique | E33: 1 | F33: 60000
A34: 44862 | C34: 1825000 | D34: Balanceado Inicio | E34: 25 | F34: =+C34/E34 -> 73000
A35: 44866 | C35: 115000 | D35: Febenlasca 1L | E35: 1 | F35: =+C35/E35 -> 115000
A36: 44869 | C36: 2190000 | D36: Balanceado Inicio | E36: 30 | F36: =+C36/E36 -> 73000
A37: 44877 | C37: 1800000 | D37: Balanceado Crecimiento | E37: 25 | F37: =+C37/E37 -> 72000
A38: 44883 | C38: 2520000 | D38: Balanceado Crecimiento | E38: 35 | F38: =+C38/E38 -> 72000
A39: 44891 | C39: 2160000 | D39: Balanceado Crecimiento | E39: 30 | F39: =+C39/E39 -> 72000
A40: 44893 | B40: 100000 | D40: Bolsas de balanceado | E40: 200 | F40: =+B40/E40 -> 500 | G40: Venialvos
...
